<?xml version="1.0" encoding="utf-8"?>
<!-- This URDF was automatically created by SolidWorks to URDF Exporter! Originally created by
Stephen Brawner (brawner@gmail.com) 
     Commit Version: 1.6.0-4-g7f85cfe  Build Version: 1.6.7995.38578
     For more information, please see http://wiki.ros.org/sw_urdf_exporter -->
<robot xmlns:xacro="http://www.ros.org/wiki/xacro">

  <link
    name="coact_base_link">
    <inertial>
      <origin
        xyz="-0.0035845 0.0019636 0.012011"
        rpy="0 0 0" />
      <mass
        value="0.07902" />
      <inertia
        ixx="4.1882E-05"
        ixy="2.5898E-07"
        ixz="-4.4967E-07"
        iyy="3.7898E-05"
        iyz="-3.1583E-07"
        izz="7.2725E-05" />
    </inertial>
    <visual>
      <origin
        xyz="0 0 0"
        rpy="0 0 0" />
      <geometry>
        <mesh
          filename="file://$(find melfa_assista_hardware)/meshes/coact_base_link.stl" />
      </geometry>
      <material
        name="">
        <color
          rgba="0.79216 0.81961 0.93333 1" />
      </material>
    </visual>
    <collision>
      <origin
        xyz="0 0 0"
        rpy="0 0 0" />
      <geometry>
        <mesh
          filename="file://$(find melfa_assista_hardware)/meshes/coact_base_link.stl" />
      </geometry>
    </collision>
  </link>
  <link
    name="housing_link">
    <inertial>
      <origin
        xyz="0.0004679 -7.9733E-06 -0.071807"
        rpy="0 0 0" />
      <mass
        value="0.38897" />
      <inertia
        ixx="0.00050627"
        ixy="5.502E-08"
        ixz="-1.027E-07"
        iyy="0.00055192"
        iyz="4.1906E-08"
        izz="0.00032568" />
    </inertial>
    <visual>
      <origin
        xyz="0 0 0"
        rpy="0 0 0" />
      <geometry>
        <mesh
          filename="file://$(find melfa_assista_hardware)/meshes/housing_link.stl" />
      </geometry>
      <material
        name="">
        <color
          rgba="0.79216 0.81961 0.93333 1" />
      </material>
    </visual>
    <collision>
      <origin
        xyz="0 0 0"
        rpy="0 0 0" />
      <geometry>
        <mesh
          filename="file://$(find melfa_assista_hardware)/meshes/housing_link.stl" />
      </geometry>
    </collision>
  </link>
  <joint
    name="housing_joint"
    type="fixed">
    <origin
      xyz="-0.00274999999999998 -0.1325 0.00274999999999998"
      rpy="1.5707963267949 0 0" />
    <parent
      link="coact_base_link" />
    <child
      link="housing_link" />
    <axis
      xyz="0 0 0" />
  </joint>
  <link
    name="hand_left_link">
    <inertial>
      <origin
        xyz="0.0015172 -0.015033 0.0033678"
        rpy="0 0 0" />
      <mass
        value="0.0034696" />
      <inertia
        ixx="2.1052E-07"
        ixy="-1.1835E-07"
        ixz="4.2799E-08"
        iyy="4.0216E-07"
        iyz="4.2388E-08"
        izz="5.2415E-07" />
    </inertial>
    <visual>
      <origin
        xyz="0 0 0"
        rpy="0 0 0" />
      <geometry>
        <mesh
          filename="file://$(find melfa_assista_hardware)/meshes/hand_left_link.stl" />
      </geometry>
      <material
        name="">
        <color
          rgba="0.79216 0.81961 0.93333 1" />
      </material>
    </visual>
    <collision>
      <origin
        xyz="0 0 0"
        rpy="0 0 0" />
      <geometry>
        <mesh
          filename="file://$(find melfa_assista_hardware)/meshes/hand_left_link.stl" />
      </geometry>
    </collision>
  </link>
  <joint name="joint_hand_left" type="prismatic">
    <origin
      xyz="0 0 0.0122"
      rpy="1.5708 0 0" />
    <parent
      link="housing_link" />
    <child
      link="hand_left_link" />
    <axis
      xyz="1 0 0" />
    <limit
      lower="0.0"
      upper="0.006"
      effort="200"
      velocity="1.0" />
  </joint>
  <link
    name="finger_left_link">
    <inertial>
      <origin
        xyz="0.01141 1.352E-08 0.024079"
        rpy="0 0 0" />
      <mass
        value="0.013672" />
      <inertia
        ixx="2.7756E-06"
        ixy="-5.3984E-13"
        ixz="1.3676E-07"
        iyy="2.5808E-06"
        iyz="1.4625E-12"
        izz="7.7774E-07" />
    </inertial>
    <visual>
      <origin
        xyz="0 0 0"
        rpy="0 0 0" />
      <geometry>
        <mesh
          filename="file://$(find melfa_assista_hardware)/meshes/finger_left_link.stl" />
      </geometry>
      <material
        name="">
        <color
          rgba="0.79608 0.82353 0.93725 1" />
      </material>
    </visual>
    <collision>
      <origin
        xyz="0 0 0"
        rpy="0 0 0" />
      <geometry>
        <mesh
          filename="file://$(find melfa_assista_hardware)/meshes/finger_left_link.stl" />
      </geometry>
    </collision>
  </link>
  <joint
    name="finger_left_joint"
    type="fixed">
    <origin
      xyz="0.0080313 -0.012 0"
      rpy="-1.5708 0 0" />
    <parent
      link="hand_left_link" />
    <child
      link="finger_left_link" />
    <axis
      xyz="0 0 0" />
  </joint>
  <link
    name="hand_right_link">
    <inertial>
      <origin
        xyz="0.0015161 -0.015033 0.0033678"
        rpy="0 0 0" />
      <mass
        value="0.0034696" />
      <inertia
        ixx="2.1052E-07"
        ixy="-1.1835E-07"
        ixz="4.2799E-08"
        iyy="4.0216E-07"
        iyz="4.2388E-08"
        izz="5.2415E-07" />
    </inertial>
    <visual>
      <origin
        xyz="0 0 0"
        rpy="0 0 0" />
      <geometry>
        <mesh
          filename="file://$(find melfa_assista_hardware)/meshes/hand_right_link.stl" />
      </geometry>
      <material
        name="">
        <color
          rgba="0.79216 0.81961 0.93333 1" />
      </material>
    </visual>
    <collision>
      <origin
        xyz="0 0 0"
        rpy="0 0 0" />
      <geometry>
        <mesh
          filename="file://$(find melfa_assista_hardware)/meshes/hand_right_link.stl" />
      </geometry>
    </collision>
  </link>
  <joint
    name="joint_hand_right"
    type="prismatic">
    <origin
      xyz="0 0 0.0122"
      rpy="1.5708 0 -3.1416" />
    <parent
      link="housing_link" />
    <child
      link="hand_right_link" />
    <axis
      xyz="1 0 0" />
    <limit
      lower="0.0"
      upper="0.006"
      effort="200"
      velocity="1.0" />
    <mimic joint="joint_hand_left" />
  </joint>
  <link
    name="finger_right_link">
    <inertial>
      <origin
        xyz="0.01141 1.352E-08 0.024079"
        rpy="0 0 0" />
      <mass
        value="0.011888" />
      <inertia
        ixx="2.4136E-06"
        ixy="-4.6943E-13"
        ixz="1.1892E-07"
        iyy="2.2441E-06"
        iyz="1.2718E-12"
        izz="6.7629E-07" />
    </inertial>
    <visual>
      <origin
        xyz="0 0 0"
        rpy="0 0 0" />
      <geometry>
        <mesh
          filename="file://$(find melfa_assista_hardware)/meshes/finger_right_link.stl" />
      </geometry>
      <material
        name="">
        <color
          rgba="0.79216 0.81961 0.93333 1" />
      </material>
    </visual>
    <collision>
      <origin
        xyz="0 0 0"
        rpy="0 0 0" />
      <geometry>
        <mesh
          filename="file://$(find melfa_assista_hardware)/meshes/finger_right_link.stl" />
      </geometry>
    </collision>
  </link>
  <joint
    name="finger_right_joint"
    type="fixed">
    <origin
      xyz="0.0080302 -0.012 0"
      rpy="-1.5708 0 0" />
    <parent
      link="hand_right_link" />
    <child
      link="finger_right_link" />
    <axis
      xyz="0 0 0" />
  </joint>

  <!-- Tool Joint Connection to the Robot -->
  <joint name="joint_tool_robot" type="fixed">
    <origin xyz="0.0 0.0 0.01" rpy="-${(pi/2)} 0.0 ${(pi/2)}" />
    <parent link="Link_6_1" />
    <child link="coact_base_link" />
  </joint>

</robot>